step1:天地图逆地址编码校验数据集坐标是否准确，原数据集1199个
Traceback (most recent call last):
  File "/home/lixuanyi/anaconda3/envs/edupre/lib/python3.9/site-packages/urllib3/connection.py", line 174, in _new_conn
    conn = connection.create_connection(
  File "/home/lixuanyi/anaconda3/envs/edupre/lib/python3.9/site-packages/urllib3/util/connection.py", line 73, in create_connection
    for res in socket.getaddrinfo(host, port, family, socket.SOCK_STREAM):
  File "/home/lixuanyi/anaconda3/envs/edupre/lib/python3.9/socket.py", line 954, in getaddrinfo
    for res in _socket.getaddrinfo(host, port, family, type, proto, flags):
socket.gaierror: [Errno -2] Name or service not known

During handling of the above exception, another exception occurred:

Traceback (most recent call last):
  File "/home/lixuanyi/anaconda3/envs/edupre/lib/python3.9/site-packages/urllib3/connectionpool.py", line 699, in urlopen
    httplib_response = self._make_request(
  File "/home/lixuanyi/anaconda3/envs/edupre/lib/python3.9/site-packages/urllib3/connectionpool.py", line 394, in _make_request
    conn.request(method, url, **httplib_request_kw)
  File "/home/lixuanyi/anaconda3/envs/edupre/lib/python3.9/site-packages/urllib3/connection.py", line 239, in request
    super(HTTPConnection, self).request(method, url, body=body, headers=headers)
  File "/home/lixuanyi/anaconda3/envs/edupre/lib/python3.9/http/client.py", line 1279, in request
    self._send_request(method, url, body, headers, encode_chunked)
  File "/home/lixuanyi/anaconda3/envs/edupre/lib/python3.9/http/client.py", line 1325, in _send_request
    self.endheaders(body, encode_chunked=encode_chunked)
  File "/home/lixuanyi/anaconda3/envs/edupre/lib/python3.9/http/client.py", line 1274, in endheaders
    self._send_output(message_body, encode_chunked=encode_chunked)
  File "/home/lixuanyi/anaconda3/envs/edupre/lib/python3.9/http/client.py", line 1034, in _send_output
    self.send(msg)
  File "/home/lixuanyi/anaconda3/envs/edupre/lib/python3.9/http/client.py", line 974, in send
    self.connect()
  File "/home/lixuanyi/anaconda3/envs/edupre/lib/python3.9/site-packages/urllib3/connection.py", line 205, in connect
    conn = self._new_conn()
  File "/home/lixuanyi/anaconda3/envs/edupre/lib/python3.9/site-packages/urllib3/connection.py", line 186, in _new_conn
    raise NewConnectionError(
urllib3.exceptions.NewConnectionError: <urllib3.connection.HTTPConnection object at 0x7f945e48b520>: Failed to establish a new connection: [Errno -2] Name or service not known

During handling of the above exception, another exception occurred:

Traceback (most recent call last):
  File "/home/lixuanyi/anaconda3/envs/edupre/lib/python3.9/site-packages/requests/adapters.py", line 439, in send
    resp = conn.urlopen(
  File "/home/lixuanyi/anaconda3/envs/edupre/lib/python3.9/site-packages/urllib3/connectionpool.py", line 755, in urlopen
    retries = retries.increment(
  File "/home/lixuanyi/anaconda3/envs/edupre/lib/python3.9/site-packages/urllib3/util/retry.py", line 574, in increment
    raise MaxRetryError(_pool, url, error or ResponseError(cause))
urllib3.exceptions.MaxRetryError: HTTPConnectionPool(host='api.tianditu.gov.cn', port=80): Max retries exceeded with url: /geocoder?parameters&tk=2423a38b3af5569af8aa521babc5e349&ds=%7B%27keyWord%27%3A+%27%E4%B9%89%E4%B9%8C%E4%B8%AD%E6%9C%AA%E6%91%87%E7%AF%AE%E5%B9%BC%E5%84%BF%E5%9B%AD%E6%9C%89%E9%99%90%E5%85%AC%E5%8F%B8%27%7D (Caused by NewConnectionError('<urllib3.connection.HTTPConnection object at 0x7f945e48b520>: Failed to establish a new connection: [Errno -2] Name or service not known'))

During handling of the above exception, another exception occurred:

Traceback (most recent call last):
  File "/home/lixuanyi/code/compete/ccf-edupre/test/test.py", line 21, in <module>
    correct1, uncorrect1, unsure1 = check_correct_origininfo(data)
  File "/home/lixuanyi/code/compete/ccf-edupre/test/../txt2poi/main.py", line 22, in check_correct_origininfo
    result, loc_v, address = tianditu.verify_loc_by_name(row_t['name'], loc)
  File "/home/lixuanyi/code/compete/ccf-edupre/test/../txt2poi/tianditu_loc.py", line 175, in verify_loc_by_name
    loc_v, _ = self.getlocbyname(name)
  File "/home/lixuanyi/code/compete/ccf-edupre/test/../txt2poi/tianditu_loc.py", line 33, in getlocbyname
    res=requests.get(url, params)
  File "/home/lixuanyi/anaconda3/envs/edupre/lib/python3.9/site-packages/requests/api.py", line 75, in get
    return request('get', url, params=params, **kwargs)
  File "/home/lixuanyi/anaconda3/envs/edupre/lib/python3.9/site-packages/requests/api.py", line 61, in request
    return session.request(method=method, url=url, **kwargs)
  File "/home/lixuanyi/anaconda3/envs/edupre/lib/python3.9/site-packages/requests/sessions.py", line 542, in request
    resp = self.send(prep, **send_kwargs)
  File "/home/lixuanyi/anaconda3/envs/edupre/lib/python3.9/site-packages/requests/sessions.py", line 655, in send
    r = adapter.send(request, **kwargs)
  File "/home/lixuanyi/anaconda3/envs/edupre/lib/python3.9/site-packages/requests/adapters.py", line 516, in send
    raise ConnectionError(e, request=request)
requests.exceptions.ConnectionError: HTTPConnectionPool(host='api.tianditu.gov.cn', port=80): Max retries exceeded with url: /geocoder?parameters&tk=2423a38b3af5569af8aa521babc5e349&ds=%7B%27keyWord%27%3A+%27%E4%B9%89%E4%B9%8C%E4%B8%AD%E6%9C%AA%E6%91%87%E7%AF%AE%E5%B9%BC%E5%84%BF%E5%9B%AD%E6%9C%89%E9%99%90%E5%85%AC%E5%8F%B8%27%7D (Caused by NewConnectionError('<urllib3.connection.HTTPConnection object at 0x7f945e48b520>: Failed to establish a new connection: [Errno -2] Name or service not known'))
